[2024-12-01T11:26:33.449+0000] {taskinstance.py:1083} INFO - Dependencies all met for <TaskInstance: car_price_prediction.predict scheduled__2022-10-05T15:00:00+00:00 [queued]>
[2024-12-01T11:26:33.461+0000] {taskinstance.py:1083} INFO - Dependencies all met for <TaskInstance: car_price_prediction.predict scheduled__2022-10-05T15:00:00+00:00 [queued]>
[2024-12-01T11:26:33.461+0000] {taskinstance.py:1279} INFO - 
--------------------------------------------------------------------------------
[2024-12-01T11:26:33.461+0000] {taskinstance.py:1280} INFO - Starting attempt 1 of 2
[2024-12-01T11:26:33.462+0000] {taskinstance.py:1281} INFO - 
--------------------------------------------------------------------------------
[2024-12-01T11:26:33.477+0000] {taskinstance.py:1300} INFO - Executing <Task(PythonOperator): predict> on 2022-10-05 15:00:00+00:00
[2024-12-01T11:26:33.485+0000] {standard_task_runner.py:55} INFO - Started process 1443 to run task
[2024-12-01T11:26:33.487+0000] {standard_task_runner.py:82} INFO - Running: ['***', 'tasks', 'run', 'car_price_prediction', 'predict', 'scheduled__2022-10-05T15:00:00+00:00', '--job-id', '484', '--raw', '--subdir', 'DAGS_FOLDER/hw_dag.py', '--cfg-path', '/tmp/tmp7z4ddvs5']
[2024-12-01T11:26:33.489+0000] {standard_task_runner.py:83} INFO - Job 484: Subtask predict
[2024-12-01T11:26:33.552+0000] {task_command.py:388} INFO - Running <TaskInstance: car_price_prediction.predict scheduled__2022-10-05T15:00:00+00:00 [running]> on host 88c3fb750b90
[2024-12-01T11:26:33.629+0000] {taskinstance.py:1509} INFO - Exporting the following env vars:
AIRFLOW_CTX_DAG_OWNER=***
AIRFLOW_CTX_DAG_ID=car_price_prediction
AIRFLOW_CTX_TASK_ID=predict
AIRFLOW_CTX_EXECUTION_DATE=2022-10-05T15:00:00+00:00
AIRFLOW_CTX_TRY_NUMBER=1
AIRFLOW_CTX_DAG_RUN_ID=scheduled__2022-10-05T15:00:00+00:00
[2024-12-01T11:26:33.630+0000] {taskinstance.py:1768} ERROR - Task failed with exception
Traceback (most recent call last):
  File "/home/airflow/.local/lib/python3.7/site-packages/airflow/operators/python.py", line 175, in execute
    return_value = self.execute_callable()
  File "/home/airflow/.local/lib/python3.7/site-packages/airflow/operators/python.py", line 192, in execute_callable
    return self.python_callable(*self.op_args, **self.op_kwargs)
  File "/opt/airflow/modules/predict.py", line 14, in predict
    with open(f'{path}/data/models/cars_pipe_202412011237.pkl', 'rb') as file:
FileNotFoundError: [Errno 2] No such file or directory: '/home/airflow/airflow_hw/data/models/cars_pipe_202412011237.pkl'
[2024-12-01T11:26:33.642+0000] {taskinstance.py:1323} INFO - Marking task as UP_FOR_RETRY. dag_id=car_price_prediction, task_id=predict, execution_date=20221005T150000, start_date=20241201T112633, end_date=20241201T112633
[2024-12-01T11:26:33.660+0000] {standard_task_runner.py:105} ERROR - Failed to execute job 484 for task predict ([Errno 2] No such file or directory: '/home/airflow/airflow_hw/data/models/cars_pipe_202412011237.pkl'; 1443)
[2024-12-01T11:26:33.699+0000] {local_task_job.py:208} INFO - Task exited with return code 1
[2024-12-01T11:26:33.728+0000] {taskinstance.py:2578} INFO - 0 downstream tasks scheduled from follow-on schedule check
