[2024-12-01T11:12:25.898+0000] {taskinstance.py:1083} INFO - Dependencies all met for <TaskInstance: car_price_prediction.predict scheduled__2022-07-09T15:00:00+00:00 [queued]>
[2024-12-01T11:12:25.907+0000] {taskinstance.py:1083} INFO - Dependencies all met for <TaskInstance: car_price_prediction.predict scheduled__2022-07-09T15:00:00+00:00 [queued]>
[2024-12-01T11:12:25.907+0000] {taskinstance.py:1279} INFO - 
--------------------------------------------------------------------------------
[2024-12-01T11:12:25.908+0000] {taskinstance.py:1280} INFO - Starting attempt 2 of 2
[2024-12-01T11:12:25.908+0000] {taskinstance.py:1281} INFO - 
--------------------------------------------------------------------------------
[2024-12-01T11:12:25.917+0000] {taskinstance.py:1300} INFO - Executing <Task(PythonOperator): predict> on 2022-07-09 15:00:00+00:00
[2024-12-01T11:12:25.922+0000] {standard_task_runner.py:55} INFO - Started process 1712 to run task
[2024-12-01T11:12:25.924+0000] {standard_task_runner.py:82} INFO - Running: ['***', 'tasks', 'run', 'car_price_prediction', 'predict', 'scheduled__2022-07-09T15:00:00+00:00', '--job-id', '141', '--raw', '--subdir', 'DAGS_FOLDER/hw_dag.py', '--cfg-path', '/tmp/tmp9_8v3yxv']
[2024-12-01T11:12:25.926+0000] {standard_task_runner.py:83} INFO - Job 141: Subtask predict
[2024-12-01T11:12:25.977+0000] {task_command.py:388} INFO - Running <TaskInstance: car_price_prediction.predict scheduled__2022-07-09T15:00:00+00:00 [running]> on host 88c3fb750b90
[2024-12-01T11:12:26.030+0000] {taskinstance.py:1509} INFO - Exporting the following env vars:
AIRFLOW_CTX_DAG_OWNER=***
AIRFLOW_CTX_DAG_ID=car_price_prediction
AIRFLOW_CTX_TASK_ID=predict
AIRFLOW_CTX_EXECUTION_DATE=2022-07-09T15:00:00+00:00
AIRFLOW_CTX_TRY_NUMBER=2
AIRFLOW_CTX_DAG_RUN_ID=scheduled__2022-07-09T15:00:00+00:00
[2024-12-01T11:12:26.031+0000] {taskinstance.py:1768} ERROR - Task failed with exception
Traceback (most recent call last):
  File "/home/airflow/.local/lib/python3.7/site-packages/airflow/operators/python.py", line 175, in execute
    return_value = self.execute_callable()
  File "/home/airflow/.local/lib/python3.7/site-packages/airflow/operators/python.py", line 192, in execute_callable
    return self.python_callable(*self.op_args, **self.op_kwargs)
  File "/opt/airflow/modules/predict.py", line 14, in predict
    with open(f'{path}/data/models/cars_pipe_202412011237.pkl', 'rb') as file:
FileNotFoundError: [Errno 2] No such file or directory: '/home/airflow/airflow_hw/data/models/cars_pipe_202412011237.pkl'
[2024-12-01T11:12:26.041+0000] {taskinstance.py:1323} INFO - Marking task as FAILED. dag_id=car_price_prediction, task_id=predict, execution_date=20220709T150000, start_date=20241201T111225, end_date=20241201T111226
[2024-12-01T11:12:26.050+0000] {standard_task_runner.py:105} ERROR - Failed to execute job 141 for task predict ([Errno 2] No such file or directory: '/home/airflow/airflow_hw/data/models/cars_pipe_202412011237.pkl'; 1712)
[2024-12-01T11:12:26.098+0000] {local_task_job.py:208} INFO - Task exited with return code 1
[2024-12-01T11:12:26.110+0000] {taskinstance.py:2578} INFO - 0 downstream tasks scheduled from follow-on schedule check
