[2024-12-01T12:12:45.109+0000] {taskinstance.py:1083} INFO - Dependencies all met for <TaskInstance: car_price_prediction.predict scheduled__2023-01-07T15:00:00+00:00 [queued]>
[2024-12-01T12:12:45.116+0000] {taskinstance.py:1083} INFO - Dependencies all met for <TaskInstance: car_price_prediction.predict scheduled__2023-01-07T15:00:00+00:00 [queued]>
[2024-12-01T12:12:45.116+0000] {taskinstance.py:1279} INFO - 
--------------------------------------------------------------------------------
[2024-12-01T12:12:45.116+0000] {taskinstance.py:1280} INFO - Starting attempt 2 of 2
[2024-12-01T12:12:45.117+0000] {taskinstance.py:1281} INFO - 
--------------------------------------------------------------------------------
[2024-12-01T12:12:45.125+0000] {taskinstance.py:1300} INFO - Executing <Task(PythonOperator): predict> on 2023-01-07 15:00:00+00:00
[2024-12-01T12:12:45.130+0000] {standard_task_runner.py:55} INFO - Started process 881 to run task
[2024-12-01T12:12:45.132+0000] {standard_task_runner.py:82} INFO - Running: ['***', 'tasks', 'run', 'car_price_prediction', 'predict', 'scheduled__2023-01-07T15:00:00+00:00', '--job-id', '842', '--raw', '--subdir', 'DAGS_FOLDER/hw_dag.py', '--cfg-path', '/tmp/tmpap1ounn1']
[2024-12-01T12:12:45.133+0000] {standard_task_runner.py:83} INFO - Job 842: Subtask predict
[2024-12-01T12:12:45.173+0000] {task_command.py:388} INFO - Running <TaskInstance: car_price_prediction.predict scheduled__2023-01-07T15:00:00+00:00 [running]> on host 88c3fb750b90
[2024-12-01T12:12:45.215+0000] {taskinstance.py:1509} INFO - Exporting the following env vars:
AIRFLOW_CTX_DAG_OWNER=***
AIRFLOW_CTX_DAG_ID=car_price_prediction
AIRFLOW_CTX_TASK_ID=predict
AIRFLOW_CTX_EXECUTION_DATE=2023-01-07T15:00:00+00:00
AIRFLOW_CTX_TRY_NUMBER=2
AIRFLOW_CTX_DAG_RUN_ID=scheduled__2023-01-07T15:00:00+00:00
[2024-12-01T12:12:45.217+0000] {taskinstance.py:1768} ERROR - Task failed with exception
Traceback (most recent call last):
  File "/home/airflow/.local/lib/python3.7/site-packages/airflow/operators/python.py", line 175, in execute
    return_value = self.execute_callable()
  File "/home/airflow/.local/lib/python3.7/site-packages/airflow/operators/python.py", line 192, in execute_callable
    return self.python_callable(*self.op_args, **self.op_kwargs)
  File "/opt/airflow/modules/predict.py", line 15, in predict
    model = dill.load(file)
  File "/home/airflow/.local/lib/python3.7/site-packages/dill/_dill.py", line 270, in load
    return Unpickler(file, ignore=ignore, **kwds).load()
  File "/home/airflow/.local/lib/python3.7/site-packages/dill/_dill.py", line 472, in load
    obj = StockUnpickler.load(self)
  File "/home/airflow/.local/lib/python3.7/site-packages/dill/_dill.py", line 462, in find_class
    return StockUnpickler.find_class(self, module, name)
AttributeError: Can't get attribute '_create_code' on <module 'dill._dill' from '/home/***/.local/lib/python3.7/site-packages/dill/_dill.py'>
[2024-12-01T12:12:45.224+0000] {taskinstance.py:1323} INFO - Marking task as FAILED. dag_id=car_price_prediction, task_id=predict, execution_date=20230107T150000, start_date=20241201T121245, end_date=20241201T121245
[2024-12-01T12:12:45.231+0000] {standard_task_runner.py:105} ERROR - Failed to execute job 842 for task predict (Can't get attribute '_create_code' on <module 'dill._dill' from '/home/***/.local/lib/python3.7/site-packages/dill/_dill.py'>; 881)
[2024-12-01T12:12:45.264+0000] {local_task_job.py:208} INFO - Task exited with return code 1
[2024-12-01T12:12:45.276+0000] {taskinstance.py:2578} INFO - 0 downstream tasks scheduled from follow-on schedule check
