[2024-12-01T11:28:40.975+0000] {taskinstance.py:1083} INFO - Dependencies all met for <TaskInstance: car_price_prediction.predict scheduled__2022-11-01T15:00:00+00:00 [queued]>
[2024-12-01T11:28:40.988+0000] {taskinstance.py:1083} INFO - Dependencies all met for <TaskInstance: car_price_prediction.predict scheduled__2022-11-01T15:00:00+00:00 [queued]>
[2024-12-01T11:28:40.988+0000] {taskinstance.py:1279} INFO - 
--------------------------------------------------------------------------------
[2024-12-01T11:28:40.989+0000] {taskinstance.py:1280} INFO - Starting attempt 1 of 2
[2024-12-01T11:28:40.989+0000] {taskinstance.py:1281} INFO - 
--------------------------------------------------------------------------------
[2024-12-01T11:28:41.004+0000] {taskinstance.py:1300} INFO - Executing <Task(PythonOperator): predict> on 2022-11-01 15:00:00+00:00
[2024-12-01T11:28:41.010+0000] {standard_task_runner.py:55} INFO - Started process 327 to run task
[2024-12-01T11:28:41.013+0000] {standard_task_runner.py:82} INFO - Running: ['***', 'tasks', 'run', 'car_price_prediction', 'predict', 'scheduled__2022-11-01T15:00:00+00:00', '--job-id', '550', '--raw', '--subdir', 'DAGS_FOLDER/hw_dag.py', '--cfg-path', '/tmp/tmpqw24r302']
[2024-12-01T11:28:41.014+0000] {standard_task_runner.py:83} INFO - Job 550: Subtask predict
[2024-12-01T11:28:41.075+0000] {task_command.py:388} INFO - Running <TaskInstance: car_price_prediction.predict scheduled__2022-11-01T15:00:00+00:00 [running]> on host 88c3fb750b90
[2024-12-01T11:28:41.148+0000] {taskinstance.py:1509} INFO - Exporting the following env vars:
AIRFLOW_CTX_DAG_OWNER=***
AIRFLOW_CTX_DAG_ID=car_price_prediction
AIRFLOW_CTX_TASK_ID=predict
AIRFLOW_CTX_EXECUTION_DATE=2022-11-01T15:00:00+00:00
AIRFLOW_CTX_TRY_NUMBER=1
AIRFLOW_CTX_DAG_RUN_ID=scheduled__2022-11-01T15:00:00+00:00
[2024-12-01T11:28:41.150+0000] {taskinstance.py:1768} ERROR - Task failed with exception
Traceback (most recent call last):
  File "/home/airflow/.local/lib/python3.7/site-packages/airflow/operators/python.py", line 175, in execute
    return_value = self.execute_callable()
  File "/home/airflow/.local/lib/python3.7/site-packages/airflow/operators/python.py", line 192, in execute_callable
    return self.python_callable(*self.op_args, **self.op_kwargs)
  File "/opt/airflow/modules/predict.py", line 14, in predict
    with open(f'{path}/data/models/cars_pipe_202412011237.pkl', 'rb') as file:
FileNotFoundError: [Errno 2] No such file or directory: 'C:/Users/user/airflow_hw/data/models/cars_pipe_202412011237.pkl'
[2024-12-01T11:28:41.161+0000] {taskinstance.py:1323} INFO - Marking task as UP_FOR_RETRY. dag_id=car_price_prediction, task_id=predict, execution_date=20221101T150000, start_date=20241201T112840, end_date=20241201T112841
[2024-12-01T11:28:41.174+0000] {standard_task_runner.py:105} ERROR - Failed to execute job 550 for task predict ([Errno 2] No such file or directory: 'C:/Users/user/airflow_hw/data/models/cars_pipe_202412011237.pkl'; 327)
[2024-12-01T11:28:41.224+0000] {local_task_job.py:208} INFO - Task exited with return code 1
[2024-12-01T11:28:41.262+0000] {taskinstance.py:2578} INFO - 0 downstream tasks scheduled from follow-on schedule check
