[2024-12-01T11:32:50.237+0000] {taskinstance.py:1083} INFO - Dependencies all met for <TaskInstance: car_price_prediction.predict scheduled__2022-11-29T15:00:00+00:00 [queued]>
[2024-12-01T11:32:50.248+0000] {taskinstance.py:1083} INFO - Dependencies all met for <TaskInstance: car_price_prediction.predict scheduled__2022-11-29T15:00:00+00:00 [queued]>
[2024-12-01T11:32:50.248+0000] {taskinstance.py:1279} INFO - 
--------------------------------------------------------------------------------
[2024-12-01T11:32:50.249+0000] {taskinstance.py:1280} INFO - Starting attempt 1 of 2
[2024-12-01T11:32:50.249+0000] {taskinstance.py:1281} INFO - 
--------------------------------------------------------------------------------
[2024-12-01T11:32:50.264+0000] {taskinstance.py:1300} INFO - Executing <Task(PythonOperator): predict> on 2022-11-29 15:00:00+00:00
[2024-12-01T11:32:50.271+0000] {standard_task_runner.py:55} INFO - Started process 1123 to run task
[2024-12-01T11:32:50.274+0000] {standard_task_runner.py:82} INFO - Running: ['***', 'tasks', 'run', 'car_price_prediction', 'predict', 'scheduled__2022-11-29T15:00:00+00:00', '--job-id', '663', '--raw', '--subdir', 'DAGS_FOLDER/hw_dag.py', '--cfg-path', '/tmp/tmpnnmec84o']
[2024-12-01T11:32:50.276+0000] {standard_task_runner.py:83} INFO - Job 663: Subtask predict
[2024-12-01T11:32:50.361+0000] {task_command.py:388} INFO - Running <TaskInstance: car_price_prediction.predict scheduled__2022-11-29T15:00:00+00:00 [running]> on host 88c3fb750b90
[2024-12-01T11:32:50.454+0000] {taskinstance.py:1509} INFO - Exporting the following env vars:
AIRFLOW_CTX_DAG_OWNER=***
AIRFLOW_CTX_DAG_ID=car_price_prediction
AIRFLOW_CTX_TASK_ID=predict
AIRFLOW_CTX_EXECUTION_DATE=2022-11-29T15:00:00+00:00
AIRFLOW_CTX_TRY_NUMBER=1
AIRFLOW_CTX_DAG_RUN_ID=scheduled__2022-11-29T15:00:00+00:00
[2024-12-01T11:32:50.456+0000] {taskinstance.py:1768} ERROR - Task failed with exception
Traceback (most recent call last):
  File "/home/airflow/.local/lib/python3.7/site-packages/airflow/operators/python.py", line 175, in execute
    return_value = self.execute_callable()
  File "/home/airflow/.local/lib/python3.7/site-packages/airflow/operators/python.py", line 192, in execute_callable
    return self.python_callable(*self.op_args, **self.op_kwargs)
  File "/opt/airflow/modules/predict.py", line 14, in predict
    with open(f'{path}/data/models/cars_pipe_202412011237.pkl', 'rb') as file:
FileNotFoundError: [Errno 2] No such file or directory: 'C:/Users/user/airflow_hw/data/models/cars_pipe_202412011237.pkl'
[2024-12-01T11:32:50.471+0000] {taskinstance.py:1323} INFO - Marking task as UP_FOR_RETRY. dag_id=car_price_prediction, task_id=predict, execution_date=20221129T150000, start_date=20241201T113250, end_date=20241201T113250
[2024-12-01T11:32:50.486+0000] {standard_task_runner.py:105} ERROR - Failed to execute job 663 for task predict ([Errno 2] No such file or directory: 'C:/Users/user/airflow_hw/data/models/cars_pipe_202412011237.pkl'; 1123)
[2024-12-01T11:32:50.528+0000] {local_task_job.py:208} INFO - Task exited with return code 1
[2024-12-01T11:32:50.550+0000] {taskinstance.py:2578} INFO - 0 downstream tasks scheduled from follow-on schedule check
