[2024-12-01T11:14:21.266+0000] {taskinstance.py:1083} INFO - Dependencies all met for <TaskInstance: car_price_prediction.predict scheduled__2022-07-21T15:00:00+00:00 [queued]>
[2024-12-01T11:14:21.272+0000] {taskinstance.py:1083} INFO - Dependencies all met for <TaskInstance: car_price_prediction.predict scheduled__2022-07-21T15:00:00+00:00 [queued]>
[2024-12-01T11:14:21.272+0000] {taskinstance.py:1279} INFO - 
--------------------------------------------------------------------------------
[2024-12-01T11:14:21.273+0000] {taskinstance.py:1280} INFO - Starting attempt 2 of 2
[2024-12-01T11:14:21.273+0000] {taskinstance.py:1281} INFO - 
--------------------------------------------------------------------------------
[2024-12-01T11:14:21.281+0000] {taskinstance.py:1300} INFO - Executing <Task(PythonOperator): predict> on 2022-07-21 15:00:00+00:00
[2024-12-01T11:14:21.286+0000] {standard_task_runner.py:55} INFO - Started process 2091 to run task
[2024-12-01T11:14:21.288+0000] {standard_task_runner.py:82} INFO - Running: ['***', 'tasks', 'run', 'car_price_prediction', 'predict', 'scheduled__2022-07-21T15:00:00+00:00', '--job-id', '204', '--raw', '--subdir', 'DAGS_FOLDER/hw_dag.py', '--cfg-path', '/tmp/tmphkbcvjkw']
[2024-12-01T11:14:21.290+0000] {standard_task_runner.py:83} INFO - Job 204: Subtask predict
[2024-12-01T11:14:21.331+0000] {task_command.py:388} INFO - Running <TaskInstance: car_price_prediction.predict scheduled__2022-07-21T15:00:00+00:00 [running]> on host 88c3fb750b90
[2024-12-01T11:14:21.375+0000] {taskinstance.py:1509} INFO - Exporting the following env vars:
AIRFLOW_CTX_DAG_OWNER=***
AIRFLOW_CTX_DAG_ID=car_price_prediction
AIRFLOW_CTX_TASK_ID=predict
AIRFLOW_CTX_EXECUTION_DATE=2022-07-21T15:00:00+00:00
AIRFLOW_CTX_TRY_NUMBER=2
AIRFLOW_CTX_DAG_RUN_ID=scheduled__2022-07-21T15:00:00+00:00
[2024-12-01T11:14:21.376+0000] {taskinstance.py:1768} ERROR - Task failed with exception
Traceback (most recent call last):
  File "/home/airflow/.local/lib/python3.7/site-packages/airflow/operators/python.py", line 175, in execute
    return_value = self.execute_callable()
  File "/home/airflow/.local/lib/python3.7/site-packages/airflow/operators/python.py", line 192, in execute_callable
    return self.python_callable(*self.op_args, **self.op_kwargs)
  File "/opt/airflow/modules/predict.py", line 14, in predict
    with open(f'{path}/data/models/cars_pipe_202412011237.pkl', 'rb') as file:
FileNotFoundError: [Errno 2] No such file or directory: '/home/airflow/airflow_hw/data/models/cars_pipe_202412011237.pkl'
[2024-12-01T11:14:21.383+0000] {taskinstance.py:1323} INFO - Marking task as FAILED. dag_id=car_price_prediction, task_id=predict, execution_date=20220721T150000, start_date=20241201T111421, end_date=20241201T111421
[2024-12-01T11:14:21.391+0000] {standard_task_runner.py:105} ERROR - Failed to execute job 204 for task predict ([Errno 2] No such file or directory: '/home/airflow/airflow_hw/data/models/cars_pipe_202412011237.pkl'; 2091)
[2024-12-01T11:14:21.420+0000] {local_task_job.py:208} INFO - Task exited with return code 1
[2024-12-01T11:14:21.432+0000] {taskinstance.py:2578} INFO - 0 downstream tasks scheduled from follow-on schedule check
