[2024-12-01T11:33:49.181+0000] {taskinstance.py:1083} INFO - Dependencies all met for <TaskInstance: car_price_prediction.predict scheduled__2022-11-20T15:00:00+00:00 [queued]>
[2024-12-01T11:33:49.187+0000] {taskinstance.py:1083} INFO - Dependencies all met for <TaskInstance: car_price_prediction.predict scheduled__2022-11-20T15:00:00+00:00 [queued]>
[2024-12-01T11:33:49.188+0000] {taskinstance.py:1279} INFO - 
--------------------------------------------------------------------------------
[2024-12-01T11:33:49.188+0000] {taskinstance.py:1280} INFO - Starting attempt 2 of 2
[2024-12-01T11:33:49.188+0000] {taskinstance.py:1281} INFO - 
--------------------------------------------------------------------------------
[2024-12-01T11:33:49.197+0000] {taskinstance.py:1300} INFO - Executing <Task(PythonOperator): predict> on 2022-11-20 15:00:00+00:00
[2024-12-01T11:33:49.202+0000] {standard_task_runner.py:55} INFO - Started process 1253 to run task
[2024-12-01T11:33:49.203+0000] {standard_task_runner.py:82} INFO - Running: ['***', 'tasks', 'run', 'car_price_prediction', 'predict', 'scheduled__2022-11-20T15:00:00+00:00', '--job-id', '674', '--raw', '--subdir', 'DAGS_FOLDER/hw_dag.py', '--cfg-path', '/tmp/tmpqn6w8727']
[2024-12-01T11:33:49.205+0000] {standard_task_runner.py:83} INFO - Job 674: Subtask predict
[2024-12-01T11:33:49.242+0000] {task_command.py:388} INFO - Running <TaskInstance: car_price_prediction.predict scheduled__2022-11-20T15:00:00+00:00 [running]> on host 88c3fb750b90
[2024-12-01T11:33:49.284+0000] {taskinstance.py:1509} INFO - Exporting the following env vars:
AIRFLOW_CTX_DAG_OWNER=***
AIRFLOW_CTX_DAG_ID=car_price_prediction
AIRFLOW_CTX_TASK_ID=predict
AIRFLOW_CTX_EXECUTION_DATE=2022-11-20T15:00:00+00:00
AIRFLOW_CTX_TRY_NUMBER=2
AIRFLOW_CTX_DAG_RUN_ID=scheduled__2022-11-20T15:00:00+00:00
[2024-12-01T11:33:49.285+0000] {taskinstance.py:1768} ERROR - Task failed with exception
Traceback (most recent call last):
  File "/home/airflow/.local/lib/python3.7/site-packages/airflow/operators/python.py", line 175, in execute
    return_value = self.execute_callable()
  File "/home/airflow/.local/lib/python3.7/site-packages/airflow/operators/python.py", line 192, in execute_callable
    return self.python_callable(*self.op_args, **self.op_kwargs)
  File "/opt/airflow/modules/predict.py", line 14, in predict
    with open(f'{path}/data/models/cars_pipe_202412011237.pkl', 'rb') as file:
FileNotFoundError: [Errno 2] No such file or directory: 'C:/Users/user/airflow_hw/data/models/cars_pipe_202412011237.pkl'
[2024-12-01T11:33:49.292+0000] {taskinstance.py:1323} INFO - Marking task as FAILED. dag_id=car_price_prediction, task_id=predict, execution_date=20221120T150000, start_date=20241201T113349, end_date=20241201T113349
[2024-12-01T11:33:49.300+0000] {standard_task_runner.py:105} ERROR - Failed to execute job 674 for task predict ([Errno 2] No such file or directory: 'C:/Users/user/airflow_hw/data/models/cars_pipe_202412011237.pkl'; 1253)
[2024-12-01T11:33:49.335+0000] {local_task_job.py:208} INFO - Task exited with return code 1
[2024-12-01T11:33:49.347+0000] {taskinstance.py:2578} INFO - 0 downstream tasks scheduled from follow-on schedule check
